Traceback (most recent call last):
  File "/home/wessels/Edit/github.com/ZoneDigestHackathon-wessels/digestify.py", line 79, in <module>
    main()
  File "/home/wessels/Edit/github.com/ZoneDigestHackathon-wessels/digestify.py", line 58, in main
    okay, err = zonemd.validate_zonemd(zone)
  File "/home/wessels/Edit/github.com/ZoneDigestHackathon-wessels/zonemd.py", line 341, in validate_zonemd
    zonemd.digest = original_digests[zonemd.algorithm]
KeyError: 1

zone-digest-hackathon.sh exited with status 1
